2022-05-18 22:42:28,811:ERROR:discord.client: Attempting a reconnect in 1.39s
Traceback (most recent call last):
  File "D:\Programming\Python\OnCreateBot\venv\lib\site-packages\aiohttp\connector.py", line 1154, in _create_direct_connection
    hosts = await asyncio.shield(host_resolved)
  File "D:\Programming\Python\OnCreateBot\venv\lib\site-packages\aiohttp\connector.py", line 880, in _resolve_host
    addrs = await self._resolver.resolve(host, port, family=self._family)
  File "D:\Programming\Python\OnCreateBot\venv\lib\site-packages\aiohttp\resolver.py", line 33, in resolve
    infos = await self._loop.getaddrinfo(
  File "C:\Users\Yashmanya\AppData\Local\Programs\Python\Python310\lib\asyncio\base_events.py", line 860, in getaddrinfo
    return await self.run_in_executor(
  File "C:\Users\Yashmanya\AppData\Local\Programs\Python\Python310\lib\concurrent\futures\thread.py", line 58, in run
    result = self.fn(*self.args, **self.kwargs)
  File "C:\Users\Yashmanya\AppData\Local\Programs\Python\Python310\lib\socket.py", line 955, in getaddrinfo
    for res in _socket.getaddrinfo(host, port, family, type, proto, flags):
socket.gaierror: [Errno 11001] getaddrinfo failed

The above exception was the direct cause of the following exception:

Traceback (most recent call last):
  File "D:\Programming\Python\OnCreateBot\venv\lib\site-packages\discord\client.py", line 579, in connect
    self.ws = await asyncio.wait_for(coro, timeout=60.0)
  File "C:\Users\Yashmanya\AppData\Local\Programs\Python\Python310\lib\asyncio\tasks.py", line 445, in wait_for
    return fut.result()
  File "D:\Programming\Python\OnCreateBot\venv\lib\site-packages\discord\gateway.py", line 358, in from_client
    gateway = gateway or await client.http.get_gateway()
  File "D:\Programming\Python\OnCreateBot\venv\lib\site-packages\discord\http.py", line 2044, in get_gateway
    data = await self.request(Route('GET', '/gateway'))
  File "D:\Programming\Python\OnCreateBot\venv\lib\site-packages\discord\http.py", line 440, in request
    async with self.__session.request(method, url, **kwargs) as response:
  File "D:\Programming\Python\OnCreateBot\venv\lib\site-packages\aiohttp\client.py", line 1138, in __aenter__
    self._resp = await self._coro
  File "D:\Programming\Python\OnCreateBot\venv\lib\site-packages\aiohttp\client.py", line 535, in _request
    conn = await self._connector.connect(
  File "D:\Programming\Python\OnCreateBot\venv\lib\site-packages\aiohttp\connector.py", line 542, in connect
    proto = await self._create_connection(req, traces, timeout)
  File "D:\Programming\Python\OnCreateBot\venv\lib\site-packages\aiohttp\connector.py", line 907, in _create_connection
    _, proto = await self._create_direct_connection(req, traces, timeout)
  File "D:\Programming\Python\OnCreateBot\venv\lib\site-packages\aiohttp\connector.py", line 1166, in _create_direct_connection
    raise ClientConnectorError(req.connection_key, exc) from exc
aiohttp.client_exceptions.ClientConnectorError: Cannot connect to host discord.com:443 ssl:default [getaddrinfo failed]
2022-05-18 22:42:31,050:ERROR:discord.client: Attempting a reconnect in 3.02s
Traceback (most recent call last):
  File "D:\Programming\Python\OnCreateBot\venv\lib\site-packages\aiohttp\connector.py", line 1154, in _create_direct_connection
    hosts = await asyncio.shield(host_resolved)
  File "D:\Programming\Python\OnCreateBot\venv\lib\site-packages\aiohttp\connector.py", line 880, in _resolve_host
    addrs = await self._resolver.resolve(host, port, family=self._family)
  File "D:\Programming\Python\OnCreateBot\venv\lib\site-packages\aiohttp\resolver.py", line 33, in resolve
    infos = await self._loop.getaddrinfo(
  File "C:\Users\Yashmanya\AppData\Local\Programs\Python\Python310\lib\asyncio\base_events.py", line 860, in getaddrinfo
    return await self.run_in_executor(
  File "C:\Users\Yashmanya\AppData\Local\Programs\Python\Python310\lib\concurrent\futures\thread.py", line 58, in run
    result = self.fn(*self.args, **self.kwargs)
  File "C:\Users\Yashmanya\AppData\Local\Programs\Python\Python310\lib\socket.py", line 955, in getaddrinfo
    for res in _socket.getaddrinfo(host, port, family, type, proto, flags):
socket.gaierror: [Errno 11001] getaddrinfo failed

The above exception was the direct cause of the following exception:

Traceback (most recent call last):
  File "D:\Programming\Python\OnCreateBot\venv\lib\site-packages\discord\client.py", line 579, in connect
    self.ws = await asyncio.wait_for(coro, timeout=60.0)
  File "C:\Users\Yashmanya\AppData\Local\Programs\Python\Python310\lib\asyncio\tasks.py", line 445, in wait_for
    return fut.result()
  File "D:\Programming\Python\OnCreateBot\venv\lib\site-packages\discord\gateway.py", line 358, in from_client
    gateway = gateway or await client.http.get_gateway()
  File "D:\Programming\Python\OnCreateBot\venv\lib\site-packages\discord\http.py", line 2044, in get_gateway
    data = await self.request(Route('GET', '/gateway'))
  File "D:\Programming\Python\OnCreateBot\venv\lib\site-packages\discord\http.py", line 440, in request
    async with self.__session.request(method, url, **kwargs) as response:
  File "D:\Programming\Python\OnCreateBot\venv\lib\site-packages\aiohttp\client.py", line 1138, in __aenter__
    self._resp = await self._coro
  File "D:\Programming\Python\OnCreateBot\venv\lib\site-packages\aiohttp\client.py", line 535, in _request
    conn = await self._connector.connect(
  File "D:\Programming\Python\OnCreateBot\venv\lib\site-packages\aiohttp\connector.py", line 542, in connect
    proto = await self._create_connection(req, traces, timeout)
  File "D:\Programming\Python\OnCreateBot\venv\lib\site-packages\aiohttp\connector.py", line 907, in _create_connection
    _, proto = await self._create_direct_connection(req, traces, timeout)
  File "D:\Programming\Python\OnCreateBot\venv\lib\site-packages\aiohttp\connector.py", line 1166, in _create_direct_connection
    raise ClientConnectorError(req.connection_key, exc) from exc
aiohttp.client_exceptions.ClientConnectorError: Cannot connect to host discord.com:443 ssl:default [getaddrinfo failed]
2022-05-18 22:42:34,082:ERROR:discord.client: Attempting a reconnect in 5.58s
Traceback (most recent call last):
  File "D:\Programming\Python\OnCreateBot\venv\lib\site-packages\aiohttp\connector.py", line 1154, in _create_direct_connection
    hosts = await asyncio.shield(host_resolved)
  File "D:\Programming\Python\OnCreateBot\venv\lib\site-packages\aiohttp\connector.py", line 880, in _resolve_host
    addrs = await self._resolver.resolve(host, port, family=self._family)
  File "D:\Programming\Python\OnCreateBot\venv\lib\site-packages\aiohttp\resolver.py", line 33, in resolve
    infos = await self._loop.getaddrinfo(
  File "C:\Users\Yashmanya\AppData\Local\Programs\Python\Python310\lib\asyncio\base_events.py", line 860, in getaddrinfo
    return await self.run_in_executor(
  File "C:\Users\Yashmanya\AppData\Local\Programs\Python\Python310\lib\concurrent\futures\thread.py", line 58, in run
    result = self.fn(*self.args, **self.kwargs)
  File "C:\Users\Yashmanya\AppData\Local\Programs\Python\Python310\lib\socket.py", line 955, in getaddrinfo
    for res in _socket.getaddrinfo(host, port, family, type, proto, flags):
socket.gaierror: [Errno 11001] getaddrinfo failed

The above exception was the direct cause of the following exception:

Traceback (most recent call last):
  File "D:\Programming\Python\OnCreateBot\venv\lib\site-packages\discord\client.py", line 579, in connect
    self.ws = await asyncio.wait_for(coro, timeout=60.0)
  File "C:\Users\Yashmanya\AppData\Local\Programs\Python\Python310\lib\asyncio\tasks.py", line 445, in wait_for
    return fut.result()
  File "D:\Programming\Python\OnCreateBot\venv\lib\site-packages\discord\gateway.py", line 358, in from_client
    gateway = gateway or await client.http.get_gateway()
  File "D:\Programming\Python\OnCreateBot\venv\lib\site-packages\discord\http.py", line 2044, in get_gateway
    data = await self.request(Route('GET', '/gateway'))
  File "D:\Programming\Python\OnCreateBot\venv\lib\site-packages\discord\http.py", line 440, in request
    async with self.__session.request(method, url, **kwargs) as response:
  File "D:\Programming\Python\OnCreateBot\venv\lib\site-packages\aiohttp\client.py", line 1138, in __aenter__
    self._resp = await self._coro
  File "D:\Programming\Python\OnCreateBot\venv\lib\site-packages\aiohttp\client.py", line 535, in _request
    conn = await self._connector.connect(
  File "D:\Programming\Python\OnCreateBot\venv\lib\site-packages\aiohttp\connector.py", line 542, in connect
    proto = await self._create_connection(req, traces, timeout)
  File "D:\Programming\Python\OnCreateBot\venv\lib\site-packages\aiohttp\connector.py", line 907, in _create_connection
    _, proto = await self._create_direct_connection(req, traces, timeout)
  File "D:\Programming\Python\OnCreateBot\venv\lib\site-packages\aiohttp\connector.py", line 1166, in _create_direct_connection
    raise ClientConnectorError(req.connection_key, exc) from exc
aiohttp.client_exceptions.ClientConnectorError: Cannot connect to host discord.com:443 ssl:default [getaddrinfo failed]
2022-05-18 22:42:39,668:ERROR:discord.client: Attempting a reconnect in 7.22s
Traceback (most recent call last):
  File "D:\Programming\Python\OnCreateBot\venv\lib\site-packages\aiohttp\connector.py", line 1154, in _create_direct_connection
    hosts = await asyncio.shield(host_resolved)
  File "D:\Programming\Python\OnCreateBot\venv\lib\site-packages\aiohttp\connector.py", line 880, in _resolve_host
    addrs = await self._resolver.resolve(host, port, family=self._family)
  File "D:\Programming\Python\OnCreateBot\venv\lib\site-packages\aiohttp\resolver.py", line 33, in resolve
    infos = await self._loop.getaddrinfo(
  File "C:\Users\Yashmanya\AppData\Local\Programs\Python\Python310\lib\asyncio\base_events.py", line 860, in getaddrinfo
    return await self.run_in_executor(
  File "C:\Users\Yashmanya\AppData\Local\Programs\Python\Python310\lib\concurrent\futures\thread.py", line 58, in run
    result = self.fn(*self.args, **self.kwargs)
  File "C:\Users\Yashmanya\AppData\Local\Programs\Python\Python310\lib\socket.py", line 955, in getaddrinfo
    for res in _socket.getaddrinfo(host, port, family, type, proto, flags):
socket.gaierror: [Errno 11001] getaddrinfo failed

The above exception was the direct cause of the following exception:

Traceback (most recent call last):
  File "D:\Programming\Python\OnCreateBot\venv\lib\site-packages\discord\client.py", line 579, in connect
    self.ws = await asyncio.wait_for(coro, timeout=60.0)
  File "C:\Users\Yashmanya\AppData\Local\Programs\Python\Python310\lib\asyncio\tasks.py", line 445, in wait_for
    return fut.result()
  File "D:\Programming\Python\OnCreateBot\venv\lib\site-packages\discord\gateway.py", line 358, in from_client
    gateway = gateway or await client.http.get_gateway()
  File "D:\Programming\Python\OnCreateBot\venv\lib\site-packages\discord\http.py", line 2044, in get_gateway
    data = await self.request(Route('GET', '/gateway'))
  File "D:\Programming\Python\OnCreateBot\venv\lib\site-packages\discord\http.py", line 440, in request
    async with self.__session.request(method, url, **kwargs) as response:
  File "D:\Programming\Python\OnCreateBot\venv\lib\site-packages\aiohttp\client.py", line 1138, in __aenter__
    self._resp = await self._coro
  File "D:\Programming\Python\OnCreateBot\venv\lib\site-packages\aiohttp\client.py", line 535, in _request
    conn = await self._connector.connect(
  File "D:\Programming\Python\OnCreateBot\venv\lib\site-packages\aiohttp\connector.py", line 542, in connect
    proto = await self._create_connection(req, traces, timeout)
  File "D:\Programming\Python\OnCreateBot\venv\lib\site-packages\aiohttp\connector.py", line 907, in _create_connection
    _, proto = await self._create_direct_connection(req, traces, timeout)
  File "D:\Programming\Python\OnCreateBot\venv\lib\site-packages\aiohttp\connector.py", line 1166, in _create_direct_connection
    raise ClientConnectorError(req.connection_key, exc) from exc
aiohttp.client_exceptions.ClientConnectorError: Cannot connect to host discord.com:443 ssl:default [getaddrinfo failed]
2022-05-18 22:42:58,605:ERROR:discord.client: Attempting a reconnect in 0.07s
Traceback (most recent call last):
  File "D:\Programming\Python\OnCreateBot\venv\lib\site-packages\aiohttp\connector.py", line 1154, in _create_direct_connection
    hosts = await asyncio.shield(host_resolved)
  File "D:\Programming\Python\OnCreateBot\venv\lib\site-packages\aiohttp\connector.py", line 880, in _resolve_host
    addrs = await self._resolver.resolve(host, port, family=self._family)
  File "D:\Programming\Python\OnCreateBot\venv\lib\site-packages\aiohttp\resolver.py", line 33, in resolve
    infos = await self._loop.getaddrinfo(
  File "C:\Users\Yashmanya\AppData\Local\Programs\Python\Python310\lib\asyncio\base_events.py", line 860, in getaddrinfo
    return await self.run_in_executor(
  File "C:\Users\Yashmanya\AppData\Local\Programs\Python\Python310\lib\concurrent\futures\thread.py", line 58, in run
    result = self.fn(*self.args, **self.kwargs)
  File "C:\Users\Yashmanya\AppData\Local\Programs\Python\Python310\lib\socket.py", line 955, in getaddrinfo
    for res in _socket.getaddrinfo(host, port, family, type, proto, flags):
socket.gaierror: [Errno 11001] getaddrinfo failed

The above exception was the direct cause of the following exception:

Traceback (most recent call last):
  File "D:\Programming\Python\OnCreateBot\venv\lib\site-packages\discord\client.py", line 579, in connect
    self.ws = await asyncio.wait_for(coro, timeout=60.0)
  File "C:\Users\Yashmanya\AppData\Local\Programs\Python\Python310\lib\asyncio\tasks.py", line 445, in wait_for
    return fut.result()
  File "D:\Programming\Python\OnCreateBot\venv\lib\site-packages\discord\gateway.py", line 358, in from_client
    gateway = gateway or await client.http.get_gateway()
  File "D:\Programming\Python\OnCreateBot\venv\lib\site-packages\discord\http.py", line 2044, in get_gateway
    data = await self.request(Route('GET', '/gateway'))
  File "D:\Programming\Python\OnCreateBot\venv\lib\site-packages\discord\http.py", line 440, in request
    async with self.__session.request(method, url, **kwargs) as response:
  File "D:\Programming\Python\OnCreateBot\venv\lib\site-packages\aiohttp\client.py", line 1138, in __aenter__
    self._resp = await self._coro
  File "D:\Programming\Python\OnCreateBot\venv\lib\site-packages\aiohttp\client.py", line 535, in _request
    conn = await self._connector.connect(
  File "D:\Programming\Python\OnCreateBot\venv\lib\site-packages\aiohttp\connector.py", line 542, in connect
    proto = await self._create_connection(req, traces, timeout)
  File "D:\Programming\Python\OnCreateBot\venv\lib\site-packages\aiohttp\connector.py", line 907, in _create_connection
    _, proto = await self._create_direct_connection(req, traces, timeout)
  File "D:\Programming\Python\OnCreateBot\venv\lib\site-packages\aiohttp\connector.py", line 1166, in _create_direct_connection
    raise ClientConnectorError(req.connection_key, exc) from exc
aiohttp.client_exceptions.ClientConnectorError: Cannot connect to host discord.com:443 ssl:default [getaddrinfo failed]
2022-05-18 22:43:10,408:ERROR:discord.client: Attempting a reconnect in 15.92s
Traceback (most recent call last):
  File "D:\Programming\Python\OnCreateBot\venv\lib\site-packages\aiohttp\connector.py", line 1154, in _create_direct_connection
    hosts = await asyncio.shield(host_resolved)
  File "D:\Programming\Python\OnCreateBot\venv\lib\site-packages\aiohttp\connector.py", line 880, in _resolve_host
    addrs = await self._resolver.resolve(host, port, family=self._family)
  File "D:\Programming\Python\OnCreateBot\venv\lib\site-packages\aiohttp\resolver.py", line 33, in resolve
    infos = await self._loop.getaddrinfo(
  File "C:\Users\Yashmanya\AppData\Local\Programs\Python\Python310\lib\asyncio\base_events.py", line 860, in getaddrinfo
    return await self.run_in_executor(
  File "C:\Users\Yashmanya\AppData\Local\Programs\Python\Python310\lib\concurrent\futures\thread.py", line 58, in run
    result = self.fn(*self.args, **self.kwargs)
  File "C:\Users\Yashmanya\AppData\Local\Programs\Python\Python310\lib\socket.py", line 955, in getaddrinfo
    for res in _socket.getaddrinfo(host, port, family, type, proto, flags):
socket.gaierror: [Errno 11001] getaddrinfo failed

The above exception was the direct cause of the following exception:

Traceback (most recent call last):
  File "D:\Programming\Python\OnCreateBot\venv\lib\site-packages\discord\client.py", line 579, in connect
    self.ws = await asyncio.wait_for(coro, timeout=60.0)
  File "C:\Users\Yashmanya\AppData\Local\Programs\Python\Python310\lib\asyncio\tasks.py", line 445, in wait_for
    return fut.result()
  File "D:\Programming\Python\OnCreateBot\venv\lib\site-packages\discord\gateway.py", line 358, in from_client
    gateway = gateway or await client.http.get_gateway()
  File "D:\Programming\Python\OnCreateBot\venv\lib\site-packages\discord\http.py", line 2044, in get_gateway
    data = await self.request(Route('GET', '/gateway'))
  File "D:\Programming\Python\OnCreateBot\venv\lib\site-packages\discord\http.py", line 440, in request
    async with self.__session.request(method, url, **kwargs) as response:
  File "D:\Programming\Python\OnCreateBot\venv\lib\site-packages\aiohttp\client.py", line 1138, in __aenter__
    self._resp = await self._coro
  File "D:\Programming\Python\OnCreateBot\venv\lib\site-packages\aiohttp\client.py", line 535, in _request
    conn = await self._connector.connect(
  File "D:\Programming\Python\OnCreateBot\venv\lib\site-packages\aiohttp\connector.py", line 542, in connect
    proto = await self._create_connection(req, traces, timeout)
  File "D:\Programming\Python\OnCreateBot\venv\lib\site-packages\aiohttp\connector.py", line 907, in _create_connection
    _, proto = await self._create_direct_connection(req, traces, timeout)
  File "D:\Programming\Python\OnCreateBot\venv\lib\site-packages\aiohttp\connector.py", line 1166, in _create_direct_connection
    raise ClientConnectorError(req.connection_key, exc) from exc
aiohttp.client_exceptions.ClientConnectorError: Cannot connect to host discord.com:443 ssl:default [getaddrinfo failed]
2022-05-18 22:43:34,069:ERROR:discord.client: Attempting a reconnect in 68.81s
Traceback (most recent call last):
  File "D:\Programming\Python\OnCreateBot\venv\lib\site-packages\aiohttp\connector.py", line 1154, in _create_direct_connection
    hosts = await asyncio.shield(host_resolved)
  File "D:\Programming\Python\OnCreateBot\venv\lib\site-packages\aiohttp\connector.py", line 880, in _resolve_host
    addrs = await self._resolver.resolve(host, port, family=self._family)
  File "D:\Programming\Python\OnCreateBot\venv\lib\site-packages\aiohttp\resolver.py", line 33, in resolve
    infos = await self._loop.getaddrinfo(
  File "C:\Users\Yashmanya\AppData\Local\Programs\Python\Python310\lib\asyncio\base_events.py", line 860, in getaddrinfo
    return await self.run_in_executor(
  File "C:\Users\Yashmanya\AppData\Local\Programs\Python\Python310\lib\concurrent\futures\thread.py", line 58, in run
    result = self.fn(*self.args, **self.kwargs)
  File "C:\Users\Yashmanya\AppData\Local\Programs\Python\Python310\lib\socket.py", line 955, in getaddrinfo
    for res in _socket.getaddrinfo(host, port, family, type, proto, flags):
socket.gaierror: [Errno 11001] getaddrinfo failed

The above exception was the direct cause of the following exception:

Traceback (most recent call last):
  File "D:\Programming\Python\OnCreateBot\venv\lib\site-packages\discord\client.py", line 579, in connect
    self.ws = await asyncio.wait_for(coro, timeout=60.0)
  File "C:\Users\Yashmanya\AppData\Local\Programs\Python\Python310\lib\asyncio\tasks.py", line 445, in wait_for
    return fut.result()
  File "D:\Programming\Python\OnCreateBot\venv\lib\site-packages\discord\gateway.py", line 358, in from_client
    gateway = gateway or await client.http.get_gateway()
  File "D:\Programming\Python\OnCreateBot\venv\lib\site-packages\discord\http.py", line 2044, in get_gateway
    data = await self.request(Route('GET', '/gateway'))
  File "D:\Programming\Python\OnCreateBot\venv\lib\site-packages\discord\http.py", line 440, in request
    async with self.__session.request(method, url, **kwargs) as response:
  File "D:\Programming\Python\OnCreateBot\venv\lib\site-packages\aiohttp\client.py", line 1138, in __aenter__
    self._resp = await self._coro
  File "D:\Programming\Python\OnCreateBot\venv\lib\site-packages\aiohttp\client.py", line 535, in _request
    conn = await self._connector.connect(
  File "D:\Programming\Python\OnCreateBot\venv\lib\site-packages\aiohttp\connector.py", line 542, in connect
    proto = await self._create_connection(req, traces, timeout)
  File "D:\Programming\Python\OnCreateBot\venv\lib\site-packages\aiohttp\connector.py", line 907, in _create_connection
    _, proto = await self._create_direct_connection(req, traces, timeout)
  File "D:\Programming\Python\OnCreateBot\venv\lib\site-packages\aiohttp\connector.py", line 1166, in _create_direct_connection
    raise ClientConnectorError(req.connection_key, exc) from exc
aiohttp.client_exceptions.ClientConnectorError: Cannot connect to host discord.com:443 ssl:default [getaddrinfo failed]
